Workbook

Sheet Main
B1: id | C1: amountClaim | D1: compensationAmount | E1: hospitalizedDate | F1: hospitalDischargeDate | G1: placeOfTreatment | H1: diagnostic | I1: tpaId | J1: createdAt | K1: Month | L1: createdAtYear | M1: createdAtYearv1 | N1: createdAtYearv2 | O1: createdAtYearv3 | P1: source | Q1: connectType | R1: co_peopleDoB | S1: age | T1: co_relationshipName | U1: co_peopleGenderName | V1: claimTypeName | W1: cleaned_diagnostic | X1: common_diagnostic_category | Y1: age_group | Z1: age_group1 | AA1: contractObjectId | AB1: peopleCityCode | AC1: peopleCity | AD1: compensationRate | AE1: contractId | AF1: claimStartDate | AG1: contractStartDate | AH1: day
A2: 0 | B2: 1b35c7826a58be899d500199a302b1a4 | C2: 809700 | D2: 251760 | E2: 45932 | G2: Bệnh viện Đa khoa Tâm Anh Hồ Chí Minh | H2: Viêm họng cấp, không đặc hiệu (J02.9), Rối loạn tiêu hoá (K30) | I2: SMART | J2: 45932.66 | K2: =MONTH(J2) -> 10 | L2: 2025 | M2: 2025 | N2: 2025 | O2: 2025 | P2: REIMBURSEMENT_CLAIM | Q2: API | R2: 45410 | S2: 1 | T2: CHILDREN | U2: FEMALE | V2: OUTPATIENT | W2: Viêm họng cấp, không đặc hiệu (j02.9), rối loạn tiêu hoá (k30) | X2: Khác | Y2: 0-17 | Z2: =IF(S2<=6,"0-6", IF(S2<=17,"7-17", IF(S2<=35,"18-35", IF(S2<=55,"36-55", "56+")))) -> 0-6 | AA2: 5af763f83815be899d50019878e5ffef | AB2: 79 | AC2: {=_xlfn.SWITCH(AB2, 79,"Thành phố Hồ Chí Minh", 1,"Thành phố Hà Nội", 35,"Tỉnh Hà Nam", 31,"Thành phố Hải Phòng", 27,"Tỉnh Bắc Ninh", 77,"Tỉnh Bà Rịa - Vũng Tàu", 48,"Thành phố Đà Nẵng", 75,"Tỉnh Đồng Nai", 38,"Tỉnh Thanh Hoá", 82,"Tỉnh Tiền Giang", 74,"Tỉnh Bình Dương", 49,"Tỉnh Quảng Nam", 51,"Tỉnh Quảng Ngãi", 52,"Tỉnh Bình Định", 40,"Tỉnh Nghệ An", "Không xác định" )} -> Thành phố Hồ Chí Minh | AD2: =ROUND((D2/C2)*100, 2) & "%" -> 31.09% | AE2: 0f2c16f83815be899d50019878e5ffe2 | AF2: =INT(E2) -> 45932 | AG2: =_xlfn.XLOOKUP(AE2, Dev!$A:$A, Dev!$B:$B, "") -> 45875.576 | AH2: =AF2-AG2 -> 56.424155
A3: 1 | B3: 4eac19f92721be899d5001999f9fc496 | C3: 2612361 | D3: 640000 | E3: 45922 | G3: Bệnh viện Đa khoa Tâm Anh Hồ Chí Minh | H3: nhiễm trùng đường ruột do vi khuẩn | I3: SMART | J3: 45931.796 | K3: =MONTH(J3) -> 10 | L3: 2025 | M3: 2025 | N3: 2025 | O3: 2025 | P3: REIMBURSEMENT_CLAIM | Q3: API | R3: 45644 | S3: 0 | T3: CHILDREN | U3: FEMALE | V3: OUTPATIENT | W3: Nhiễm trùng đường ruột do vi khuẩn | X3: Tiêu hóa | Y3: 0-17 | Z3: =IF(S3<=6,"0-6", IF(S3<=17,"7-17", IF(S3<=35,"18-35", IF(S3<=55,"36-55", "56+")))) -> 0-6 | AA3: 43504efd7f8bbe899d50019449ba5778 | AB3: 79 | AC3: {=_xlfn.SWITCH(AB3, 79,"Thành phố Hồ Chí Minh", 1,"Thành phố Hà Nội", 35,"Tỉnh Hà Nam", 31,"Thành phố Hải Phòng", 27,"Tỉnh Bắc Ninh", 77,"Tỉnh Bà Rịa - Vũng Tàu", 48,"Thành phố Đà Nẵng", 75,"Tỉnh Đồng Nai", 38,"Tỉnh Thanh Hoá", 82,"Tỉnh Tiền Giang", 74,"Tỉnh Bình Dương", 49,"Tỉnh Quảng Nam", 51,"Tỉnh Quảng Ngãi", 52,"Tỉnh Bình Định", 40,"Tỉnh Nghệ An", "Không xác định" )} -> Thành phố Hồ Chí Minh | AD3: =ROUND((D3/C3)*100, 2) & "%" -> 24.5% | AE3: f784f0fc7f8bbe899d50019449ba576b | AF3: =INT(E3) -> 45922 | AG3: =_xlfn.XLOOKUP(AE3, Dev!$A:$A, Dev!$B:$B, "") -> 45674 | AH3: =AF3-AG3 -> 248
A4: 2 | B4: 0a9513a74463be899d50019998809c9f | C4: 346000 | D4: 346000 | E4: 45925 | F4: 45926 | G4: Bệnh viện Nhi Trung ương | H4: Viêm phổi dần ổn định | I4: SMART | J4: 45930.407 | K4: =MONTH(J4) -> 9 | L4: 2025 | M4: 2025 | N4: 2025 | O4: 2025 | P4: REIMBURSEMENT_CLAIM | Q4: API | R4: 45747 | S4: 0 | T4: CHILDREN | U4: MALE | V4: OUTPATIENT | W4: Viêm phổi dần ổn định | X4: Hô hấp | Y4: 0-17 | Z4: =IF(S4<=6,"0-6", IF(S4<=17,"7-17", IF(S4<=35,"18-35", IF(S4<=55,"36-55", "56+")))) -> 0-6 | AA4: 1136ccf87a1bbe899d50019753f4db5d | AB4: 1 | AC4: {=_xlfn.SWITCH(AB4, 79,"Thành phố Hồ Chí Minh", 1,"Thành phố Hà Nội", 35,"Tỉnh Hà Nam", 31,"Thành phố Hải Phòng", 27,"Tỉnh Bắc Ninh", 77,"Tỉnh Bà Rịa - Vũng Tàu", 48,"Thành phố Đà Nẵng", 75,"Tỉnh Đồng Nai", 38,"Tỉnh Thanh Hoá", 82,"Tỉnh Tiền Giang", 74,"Tỉnh Bình Dương", 49,"Tỉnh Quảng Nam", 51,"Tỉnh Quảng Ngãi", 52,"Tỉnh Bình Định", 40,"Tỉnh Nghệ An", "Không xác định" )} -> Thành phố Hà Nội | AD4: =ROUND((D4/C4)*100, 2) & "%" -> 100% | AE4: 7a9e22a67a1bbe899d50019753f4da8e | AF4: =INT(E4) -> 45925 | AG4: =_xlfn.XLOOKUP(AE4, Dev!$A:$A, Dev!$B:$B, "") -> 45818.674 | AH4: =AF4-AG4 -> 106.32574
A5: 3 | B5: ea18e5fb4463be899d50019998775412 | C5: 1333550 | D5: 568550 | E5: 45922 | F5: 45922 | G5: Bệnh viện Nhi Trung ương | H5: Viêm phổi không đặc hiệu | I5: SMART | J5: 45930.403 | K5: =MONTH(J5) -> 9 | L5: 2025 | M5: 2025 | N5: 2025 | O5: 2025 | P5: REIMBURSEMENT_CLAIM | Q5: API | R5: 45747 | S5: 0 | T5: CHILDREN | U5: MALE | V5: OUTPATIENT | W5: Viêm phổi không đặc hiệu | X5: Hô hấp | Y5: 0-17 | Z5: =IF(S5<=6,"0-6", IF(S5<=17,"7-17", IF(S5<=35,"18-35", IF(S5<=55,"36-55", "56+")))) -> 0-6 | AA5: 1136ccf87a1bbe899d50019753f4db5d | AB5: 1 | AC5: {=_xlfn.SWITCH(AB5, 79,"Thành phố Hồ Chí Minh", 1,"Thành phố Hà Nội", 35,"Tỉnh Hà Nam", 31,"Thành phố Hải Phòng", 27,"Tỉnh Bắc Ninh", 77,"Tỉnh Bà Rịa - Vũng Tàu", 48,"Thành phố Đà Nẵng", 75,"Tỉnh Đồng Nai", 38,"Tỉnh Thanh Hoá", 82,"Tỉnh Tiền Giang", 74,"Tỉnh Bình Dương", 49,"Tỉnh Quảng Nam", 51,"Tỉnh Quảng Ngãi", 52,"Tỉnh Bình Định", 40,"Tỉnh Nghệ An", "Không xác định" )} -> Thành phố Hà Nội | AD5: =ROUND((D5/C5)*100, 2) & "%" -> 42.63% | AE5: 7a9e22a67a1bbe899d50019753f4da8e | AF5: =INT(E5) -> 45922 | AG5: =_xlfn.XLOOKUP(AE5, Dev!$A:$A, Dev!$B:$B, "") -> 45818.674 | AH5: =AF5-AG5 -> 103.32574
A6: 4 | B6: b123709656c5be899d500199869bf8fe | C6: 1559900 | D6: 105600 | E6: 45923 | F6: 45925 | G6: Bệnh viện Nhi Trung ương - Trung tâm Quốc tế | H6: Rối loạn tiêu hoá-Viêm phế quản | I6: SMART | J6: 45926.936 | K6: =MONTH(J6) -> 9 | L6: 2025 | M6: 2025 | N6: 2025 | O6: 2025 | P6: REIMBURSEMENT_CLAIM | Q6: API | R6: 45283 | S6: 1 | T6: CHILDREN | U6: MALE | V6: OUTPATIENT | W6: Rối loạn tiêu hoá-viêm phế quản | X6: Tiêu hóa | Y6: 0-17 | Z6: =IF(S6<=6,"0-6", IF(S6<=17,"7-17", IF(S6<=35,"18-35", IF(S6<=55,"36-55", "56+")))) -> 0-6 | AA6: 3ecf7efb75c8be899d5001956abd408b | AB6: 35 | AC6: {=_xlfn.SWITCH(AB6, 79,"Thành phố Hồ Chí Minh", 1,"Thành phố Hà Nội", 35,"Tỉnh Hà Nam", 31,"Thành phố Hải Phòng", 27,"Tỉnh Bắc Ninh", 77,"Tỉnh Bà Rịa - Vũng Tàu", 48,"Thành phố Đà Nẵng", 75,"Tỉnh Đồng Nai", 38,"Tỉnh Thanh Hoá", 82,"Tỉnh Tiền Giang", 74,"Tỉnh Bình Dương", 49,"Tỉnh Quảng Nam", 51,"Tỉnh Quảng Ngãi", 52,"Tỉnh Bình Định", 40,"Tỉnh Nghệ An", "Không xác định" )} -> Tỉnh Hà Nam | AD6: =ROUND((D6/C6)*100, 2) & "%" -> 6.77% | AE6: 9738e3f975c8be899d5001956abd3fd9 | AF6: =INT(E6) -> 45923 | AG6: =_xlfn.XLOOKUP(AE6, Dev!$A:$A, Dev!$B:$B, "") -> 45723.678 | AH6: =AF6-AG6 -> 199.32238
A7: 5 | B7: 501525f956c5be899d5001998694fe91 | C7: 1300000 | D7: 800000 | E7: 45921 | F7: 45921 | G7: Bệnh viện Nhi Trung ương - Trung tâm Quốc tế | H7: Viêm phế quản | I7: SMART | J7: 45926.929 | K7: =MONTH(J7) -> 9 | L7: 2025 | M7: 2025 | N7: 2025 | O7: 2025 | P7: REIMBURSEMENT_CLAIM | Q7: API | R7: 45283 | S7: 1 | T7: CHILDREN | U7: MALE | V7: OUTPATIENT | W7: Viêm phế quản | X7: Khác | Y7: 0-17 | Z7: =IF(S7<=6,"0-6", IF(S7<=17,"7-17", IF(S7<=35,"18-35", IF(S7<=55,"36-55", "56+")))) -> 0-6 | AA7: 3ecf7efb75c8be899d5001956abd408b | AB7: 35 | AC7: {=_xlfn.SWITCH(AB7, 79,"Thành phố Hồ Chí Minh", 1,"Thành phố Hà Nội", 35,"Tỉnh Hà Nam", 31,"Thành phố Hải Phòng", 27,"Tỉnh Bắc Ninh", 77,"Tỉnh Bà Rịa - Vũng Tàu", 48,"Thành phố Đà Nẵng", 75,"Tỉnh Đồng Nai", 38,"Tỉnh Thanh Hoá", 82,"Tỉnh Tiền Giang", 74,"Tỉnh Bình Dương", 49,"Tỉnh Quảng Nam", 51,"Tỉnh Quảng Ngãi", 52,"Tỉnh Bình Định", 40,"Tỉnh Nghệ An", "Không xác định" )} -> Tỉnh Hà Nam | AD7: =ROUND((D7/C7)*100, 2) & "%" -> 61.54% | AE7: 9738e3f975c8be899d5001956abd3fd9 | AF7: =INT(E7) -> 45921 | AG7: =_xlfn.XLOOKUP(AE7, Dev!$A:$A, Dev!$B:$B, "") -> 45723.678 | AH7: =AF7-AG7 -> 197.32238
A8: 6 | B8: 03a7146656c5be899d50019984c98f96 | C8: 363290 | D8: 363290 | E8: 45925 | F8: 45925 | G8: Bệnh viện Nhi Đồng I | H8: Bệnh tay chân miệng độ 1 ngày 9 - Nhiễm trùng đường ruột do vi khuẩn | I8: SMART | J8: 45926.579 | K8: =MONTH(J8) -> 9 | L8: 2025 | M8: 2025 | N8: 2025 | O8: 2025 | P8: REIMBURSEMENT_CLAIM | Q8: API | R8: 44269 | S8: 4 | T8: CHILDREN | U8: MALE | V8: OUTPATIENT | W8: Bệnh tay chân miệng độ 1 ngày 9 - nhiễm trùng đường ruột do vi khuẩn | X8: Tiêu hóa | Y8: 0-17 | Z8: =IF(S8<=6,"0-6", IF(S8<=17,"7-17", IF(S8<=35,"18-35", IF(S8<=55,"36-55", "56+")))) -> 0-6 | AA8: e7056dfc7b61be899d500195376d0bdf | AB8: 79 | AC8: {=_xlfn.SWITCH(AB8, 79,"Thành phố Hồ Chí Minh", 1,"Thành phố Hà Nội", 35,"Tỉnh Hà Nam", 31,"Thành phố Hải Phòng", 27,"Tỉnh Bắc Ninh", 77,"Tỉnh Bà Rịa - Vũng Tàu", 48,"Thành phố Đà Nẵng", 75,"Tỉnh Đồng Nai", 38,"Tỉnh Thanh Hoá", 82,"Tỉnh Tiền Giang", 74,"Tỉnh Bình Dương", 49,"Tỉnh Quảng Nam", 51,"Tỉnh Quảng Ngãi", 52,"Tỉnh Bình Định", 40,"Tỉnh Nghệ An", "Không xác định" )} -> Thành phố Hồ Chí Minh | AD8: =ROUND((D8/C8)*100, 2) & "%" -> 100% | AE8: 9c3910fb7b61be899d500195376d0bcd | AF8: =INT(E8) -> 45925 | AG8: =_xlfn.XLOOKUP(AE8, Dev!$A:$A, Dev!$B:$B, "") -> 45689 | AH8: =AF8-AG8 -> 236
A9: 7 | B9: 0fa33b1256c5be899d5001998450f526 | C9: 640000 | D9: 640000 | E9: 45897 | F9: 45905 | G9: Bệnh viện Đa khoa Phương Đông | H9: viên phế quản phổi, viêm tai giữa ứ dịch 2 bên, viêm mũi họng amidan cấp, nấm miệng, rối loạn tiêu hoá | I9: SMART | J9: 45926.499 | K9: =MONTH(J9) -> 9 | L9: 2025 | M9: 2025 | N9: 2025 | O9: 2025 | P9: REIMBURSEMENT_CLAIM | Q9: API | R9: 45573 | S9: 1 | T9: CHILDREN | U9: MALE | V9: HOSPITALIZATION ALLOWANCE | W9: Viên phế quản phổi, viêm tai giữa ứ dịch 2 bên, viêm mũi họng amidan cấp, nấm miệng, rối loạn tiêu hoá | X9: Hô hấp | Y9: 0-17 | Z9: =IF(S9<=6,"0-6", IF(S9<=17,"7-17", IF(S9<=35,"18-35", IF(S9<=55,"36-55", "56+")))) -> 0-6 | AA9: 8cee67fa1e92be899d500196e8e71072 | AB9: 1 | AC9: {=_xlfn.SWITCH(AB9, 79,"Thành phố Hồ Chí Minh", 1,"Thành phố Hà Nội", 35,"Tỉnh Hà Nam", 31,"Thành phố Hải Phòng", 27,"Tỉnh Bắc Ninh", 77,"Tỉnh Bà Rịa - Vũng Tàu", 48,"Thành phố Đà Nẵng", 75,"Tỉnh Đồng Nai", 38,"Tỉnh Thanh Hoá", 82,"Tỉnh Tiền Giang", 74,"Tỉnh Bình Dương", 49,"Tỉnh Quảng Nam", 51,"Tỉnh Quảng Ngãi", 52,"Tỉnh Bình Định", 40,"Tỉnh Nghệ An", "Không xác định" )} -> Thành phố Hà Nội | AD9: =ROUND((D9/C9)*100, 2) & "%" -> 100% | AE9: 31232afa1e92be899d500196e8e71058 | AF9: =INT(E9) -> 45897 | AG9: =_xlfn.XLOOKUP(AE9, Dev!$A:$A, Dev!$B:$B, "") -> 45797.886 | AH9: =AF9-AG9 -> 99.113576
A10: 8 | B10: baeb74f356c5be899d50019983f84942 | C10: 481500 | D10: 365200 | E10: 45887 | F10: 45887 | G10: PHÒNG KHÁM NHI KINDERHEALTH QUẬN 7 | H10: viêm thanh quản cấp (J04.0) Viêm mũi họng cấp J00 | I10: SMART | J10: 45926.421 | K10: =MONTH(J10) -> 9 | L10: 2025 | M10: 2025 | N10: 2025 | O10: 2025 | P10: REIMBURSEMENT_CLAIM | Q10: API | R10: 44507 | S10: 3 | T10: CHILDREN | U10: MALE | V10: OUTPATIENT | W10: Viêm thanh quản cấp (j04.0) viêm mũi họng cấp j00 | X10: Hô hấp | Y10: 0-17 | Z10: =IF(S10<=6,"0-6", IF(S10<=17,"7-17", IF(S10<=35,"18-35", IF(S10<=55,"36-55", "56+")))) -> 0-6 | AA10: b4041b76168ebe899d5001934d218ce9 | AB10: 79 | AC10: {=_xlfn.SWITCH(AB10, 79,"Thành phố Hồ Chí Minh", 1,"Thành phố Hà Nội", 35,"Tỉnh Hà Nam", 31,"Thành phố Hải Phòng", 27,"Tỉnh Bắc Ninh", 77,"Tỉnh Bà Rịa - Vũng Tàu", 48,"Thành phố Đà Nẵng", 75,"Tỉnh Đồng Nai", 38,"Tỉnh Thanh Hoá", 82,"Tỉnh Tiền Giang", 74,"Tỉnh Bình Dương", 49,"Tỉnh Quảng Nam", 51,"Tỉnh Quảng Ngãi", 52,"Tỉnh Bình Định", 40,"Tỉnh Nghệ An", "Không xác định" )} -> Thành phố Hồ Chí Minh | AD10: =ROUND((D10/C10)*100, 2) & "%" -> 75.85% | AE10: 6938cdb5168ebe899d5001934d218cda | AF10: =INT(E10) -> 45887 | AG10: =_xlfn.XLOOKUP(AE10, Dev!$A:$A, Dev!$B:$B, "") -> 45618.508 | AH10: =AF10-AG10 -> 268.49229
A11: 9 | B11: f13834a3342bbe899d5001997f707212 | C11: 534650 | D11: 384650 | E11: 45923 | F11: 45923 | G11: Bệnh viện Nhi Đồng I | H11: Bệnh tay chân miệng độ 1 ngày 6 - Nhiễm trùng đường ruột do vi khuẩn | I11: SMART | J11: 45925.541 | K11: =MONTH(J11) -> 9 | L11: 2025 | M11: 2025 | N11: 2025 | O11: 2025 | P11: REIMBURSEMENT_CLAIM | Q11: API | R11: 44269 | S11: 4 | T11: CHILDREN | U11: MALE | V11: OUTPATIENT | W11: Bệnh tay chân miệng độ 1 ngày 6 - nhiễm trùng đường ruột do vi khuẩn | X11: Tiêu hóa | Y11: 0-17 | Z11: =IF(S11<=6,"0-6", IF(S11<=17,"7-17", IF(S11<=35,"18-35", IF(S11<=55,"36-55", "56+")))) -> 0-6 | AA11: e7056dfc7b61be899d500195376d0bdf | AB11: 79 | AC11: {=_xlfn.SWITCH(AB11, 79,"Thành phố Hồ Chí Minh", 1,"Thành phố Hà Nội", 35,"Tỉnh Hà Nam", 31,"Thành phố Hải Phòng", 27,"Tỉnh Bắc Ninh", 77,"Tỉnh Bà Rịa - Vũng Tàu", 48,"Thành phố Đà Nẵng", 75,"Tỉnh Đồng Nai", 38,"Tỉnh Thanh Hoá", 82,"Tỉnh Tiền Giang", 74,"Tỉnh Bình Dương", 49,"Tỉnh Quảng Nam", 51,"Tỉnh Quảng Ngãi", 52,"Tỉnh Bình Định", 40,"Tỉnh Nghệ An", "Không xác định" )} -> Thành phố Hồ Chí Minh | AD11: =ROUND((D11/C11)*100, 2) & "%" -> 71.94% | AE11: 9c3910fb7b61be899d500195376d0bcd | AF11: =INT(E11) -> 45923 | AG11: =_xlfn.XLOOKUP(AE11, Dev!$A:$A, Dev!$B:$B, "") -> 45689 | AH11: =AF11-AG11 -> 234
A12: 10 | B12: 8ce64a50342bbe899d5001997f6d375b | C12: 307244 | D12: 300424 | E12: 45921 | F12: 45921 | G12: Bệnh viện Nhi Đồng I | H12: Bệnh tay chân miệng độ 1 ngày 4 | I12: SMART | J12: 45925.537 | K12: =MONTH(J12) -> 9 | L12: 2025 | M12: 2025 | N12: 2025 | O12: 2025 | P12: REIMBURSEMENT_CLAIM | Q12: API | R12: 44269 | S12: 4 | T12: CHILDREN | U12: MALE | V12: OUTPATIENT | W12: Bệnh tay chân miệng độ 1 ngày 4 | X12: Khác | Y12: 0-17 | Z12: =IF(S12<=6,"0-6", IF(S12<=17,"7-17", IF(S12<=35,"18-35", IF(S12<=55,"36-55", "56+")))) -> 0-6 | AA12: e7056dfc7b61be899d500195376d0bdf | AB12: 79 | AC12: {=_xlfn.SWITCH(AB12, 79,"Thành phố Hồ Chí Minh", 1,"Thành phố Hà Nội", 35,"Tỉnh Hà Nam", 31,"Thành phố Hải Phòng", 27,"Tỉnh Bắc Ninh", 77,"Tỉnh Bà Rịa - Vũng Tàu", 48,"Thành phố Đà Nẵng", 75,"Tỉnh Đồng Nai", 38,"Tỉnh Thanh Hoá", 82,"Tỉnh Tiền Giang", 74,"Tỉnh Bình Dương", 49,"Tỉnh Quảng Nam", 51,"Tỉnh Quảng Ngãi", 52,"Tỉnh Bình Định", 40,"Tỉnh Nghệ An", "Không xác định" )} -> Thành phố Hồ Chí Minh | AD12: =ROUND((D12/C12)*100, 2) & "%" -> 97.78% | AE12: 9c3910fb7b61be899d500195376d0bcd | AF12: =INT(E12) -> 45921 | AG12: =_xlfn.XLOOKUP(AE12, Dev!$A:$A, Dev!$B:$B, "") -> 45689 | AH12: =AF12-AG12 -> 232
A13: 11 | B13: a53759f9342bbe899d5001997f69511d | C13: 387472 | D13: 387472 | E13: 45919 | F13: 45919 | G13: Bệnh viện Nhi Đồng I | H13: Viêm mũi họng | I13: SMART | J13: 45925.535 | K13: =MONTH(J13) -> 9 | L13: 2025 | M13: 2025 | N13: 2025 | O13: 2025 | P13: REIMBURSEMENT_CLAIM | Q13: API | R13: 44269 | S13: 4 | T13: CHILDREN | U13: MALE | V13: OUTPATIENT | W13: Viêm mũi họng | X13: Hô hấp | Y13: 0-17 | Z13: =IF(S13<=6,"0-6", IF(S13<=17,"7-17", IF(S13<=35,"18-35", IF(S13<=55,"36-55", "56+")))) -> 0-6 | AA13: e7056dfc7b61be899d500195376d0bdf | AB13: 79 | AC13: {=_xlfn.SWITCH(AB13, 79,"Thành phố Hồ Chí Minh", 1,"Thành phố Hà Nội", 35,"Tỉnh Hà Nam", 31,"Thành phố Hải Phòng", 27,"Tỉnh Bắc Ninh", 77,"Tỉnh Bà Rịa - Vũng Tàu", 48,"Thành phố Đà Nẵng", 75,"Tỉnh Đồng Nai", 38,"Tỉnh Thanh Hoá", 82,"Tỉnh Tiền Giang", 74,"Tỉnh Bình Dương", 49,"Tỉnh Quảng Nam", 51,"Tỉnh Quảng Ngãi", 52,"Tỉnh Bình Định", 40,"Tỉnh Nghệ An", "Không xác định" )} -> Thành phố Hồ Chí Minh | AD13: =ROUND((D13/C13)*100, 2) & "%" -> 100% | AE13: 9c3910fb7b61be899d500195376d0bcd | AF13: =INT(E13) -> 45919 | AG13: =_xlfn.XLOOKUP(AE13, Dev!$A:$A, Dev!$B:$B, "") -> 45689 | AH13: =AF13-AG13 -> 230
A14: 12 | B14: 1655e2c53b75be899d5001996b2d0708 | C14: 798635 | D14: 653135 | E14: 45921 | G14: Bệnh Viện Nhi Đồng II | H14: Viêm họng cấp , sốt | I14: SMART | J14: 45923.576 | K14: =MONTH(J14) -> 9 | L14: 2025 | M14: 2025 | N14: 2025 | O14: 2025 | P14: REIMBURSEMENT_CLAIM | Q14: API | R14: 43048 | S14: 7 | T14: CHILDREN | U14: FEMALE | V14: OUTPATIENT | W14: Viêm họng cấp , sốt | X14: Hô hấp | Y14: 0-17 | Z14: =IF(S14<=6,"0-6", IF(S14<=17,"7-17", IF(S14<=35,"18-35", IF(S14<=55,"36-55", "56+")))) -> 7-17 | AA14: 1f9f9507168ebe899d500193af9b883f | AB14: 79 | AC14: {=_xlfn.SWITCH(AB14, 79,"Thành phố Hồ Chí Minh", 1,"Thành phố Hà Nội", 35,"Tỉnh Hà Nam", 31,"Thành phố Hải Phòng", 27,"Tỉnh Bắc Ninh", 77,"Tỉnh Bà Rịa - Vũng Tàu", 48,"Thành phố Đà Nẵng", 75,"Tỉnh Đồng Nai", 38,"Tỉnh Thanh Hoá", 82,"Tỉnh Tiền Giang", 74,"Tỉnh Bình Dương", 49,"Tỉnh Quảng Nam", 51,"Tỉnh Quảng Ngãi", 52,"Tỉnh Bình Định", 40,"Tỉnh Nghệ An", "Không xác định" )} -> Thành phố Hồ Chí Minh | AD14: =ROUND((D14/C14)*100, 2) & "%" -> 81.78% | AE14: c3d35846168ebe899d500193af9b8828 | AF14: =INT(E14) -> 45921 | AG14: =_xlfn.XLOOKUP(AE14, Dev!$A:$A, Dev!$B:$B, "") -> 45631 | AH14: =AF14-AG14 -> 290
A15: 13 | B15: 33d6b0fe0963be899d500199718c0372 | C15: 4029209 | D15: 2359809 | E15: 45917 | F15: 45919 | G15: Khác | H15: Buồn nôn và nôn, rối loạn tiêu hóa | I15: SMART | J15: 45922.843 | K15: =MONTH(J15) -> 9 | L15: 2025 | M15: 2025 | N15: 2025 | O15: 2025 | P15: REIMBURSEMENT_CLAIM | Q15: API | R15: 45650 | S15: 0 | T15: CHILDREN | U15: MALE | V15: INPATIENT | W15: Buồn nôn và nôn, rối loạn tiêu hóa | X15: Tiêu hóa | Y15: 0-17 | Z15: =IF(S15<=6,"0-6", IF(S15<=17,"7-17", IF(S15<=35,"18-35", IF(S15<=55,"36-55", "56+")))) -> 0-6 | AA15: 82097e071eecbe899d500194f39980eb | AB15: 31 | AC15: {=_xlfn.SWITCH(AB15, 79,"Thành phố Hồ Chí Minh", 1,"Thành phố Hà Nội", 35,"Tỉnh Hà Nam", 31,"Thành phố Hải Phòng", 27,"Tỉnh Bắc Ninh", 77,"Tỉnh Bà Rịa - Vũng Tàu", 48,"Thành phố Đà Nẵng", 75,"Tỉnh Đồng Nai", 38,"Tỉnh Thanh Hoá", 82,"Tỉnh Tiền Giang", 74,"Tỉnh Bình Dương", 49,"Tỉnh Quảng Nam", 51,"Tỉnh Quảng Ngãi", 52,"Tỉnh Bình Định", 40,"Tỉnh Nghệ An", "Không xác định" )} -> Thành phố Hải Phòng | AD15: =ROUND((D15/C15)*100, 2) & "%" -> 58.57% | AE15: 373d21561eecbe899d500194f39980db | AF15: =INT(E15) -> 45917 | AG15: =_xlfn.XLOOKUP(AE15, Dev!$A:$A, Dev!$B:$B, "") -> 45700.543 | AH15: =AF15-AG15 -> 216.45703
A16: 14 | B16: 0d2db3f90963be899d5001997174301d | C16: 2517275 | D16: 1085820 | E16: 45922 | F16: 45922 | G16: BỆNH VIỆN ĐA KHOA QUỐC TẾ VINMEC HẢI PHÒNG | H16: Viêm phế quản phổi | I16: SMART | J16: 45922.824 | K16: =MONTH(J16) -> 9 | L16: 2025 | M16: 2025 | N16: 2025 | O16: 2025 | P16: REIMBURSEMENT_CLAIM | Q16: API | R16: 45636 | S16: 0 | T16: CHILDREN | U16: FEMALE | V16: OUTPATIENT | W16: Viêm phế quản phổi | X16: Hô hấp | Y16: 0-17 | Z16: =IF(S16<=6,"0-6", IF(S16<=17,"7-17", IF(S16<=35,"18-35", IF(S16<=55,"36-55", "56+")))) -> 0-6 | AA16: 2a6826fb6fcbbe899d500195fac295c7 | AB16: 31 | AC16: {=_xlfn.SWITCH(AB16, 79,"Thành phố Hồ Chí Minh", 1,"Thành phố Hà Nội", 35,"Tỉnh Hà Nam", 31,"Thành phố Hải Phòng", 27,"Tỉnh Bắc Ninh", 77,"Tỉnh Bà Rịa - Vũng Tàu", 48,"Thành phố Đà Nẵng", 75,"Tỉnh Đồng Nai", 38,"Tỉnh Thanh Hoá", 82,"Tỉnh Tiền Giang", 74,"Tỉnh Bình Dương", 49,"Tỉnh Quảng Nam", 51,"Tỉnh Quảng Ngãi", 52,"Tỉnh Bình Định", 40,"Tỉnh Nghệ An", "Không xác định" )} -> Thành phố Hải Phòng | AD16: =ROUND((D16/C16)*100, 2) & "%" -> 43.13% | AE16: de9cd8fa6fcbbe899d500195fac295b6 | AF16: =INT(E16) -> 45922 | AG16: =_xlfn.XLOOKUP(AE16, Dev!$A:$A, Dev!$B:$B, "") -> 45751.644 | AH16: =AF16-AG16 -> 170.35631
A17: 15 | B17: ee1defe13b75be899d5001996b28748b | C17: 1437000 | D17: 846318 | E17: 45916 | F17: 45920 | G17: Bệnh viện đa khoa Kinh Bắc II | H17: Viêm phế quản cấp, Tay chân miệng, Viêm amydan, Viêm V.A cấp | I17: SMART | J17: 45921.603 | K17: =MONTH(J17) -> 9 | L17: 2025 | M17: 2025 | N17: 2025 | O17: 2025 | P17: REIMBURSEMENT_CLAIM | Q17: API | R17: 45487 | S17: 1 | T17: CHILDREN | U17: MALE | V17: HOSPITALIZATION ALLOWANCE | W17: Viêm phế quản cấp, tay chân miệng, viêm amydan, viêm v.a cấp | X17: Khác | Y17: 0-17 | Z17: =IF(S17<=6,"0-6", IF(S17<=17,"7-17", IF(S17<=35,"18-35", IF(S17<=55,"36-55", "56+")))) -> 0-6 | AA17: b1231cb26fcbbe899d500195ec39357c | AB17: 27 | AC17: {=_xlfn.SWITCH(AB17, 79,"Thành phố Hồ Chí Minh", 1,"Thành phố Hà Nội", 35,"Tỉnh Hà Nam", 31,"Thành phố Hải Phòng", 27,"Tỉnh Bắc Ninh", 77,"Tỉnh Bà Rịa - Vũng Tàu", 48,"Thành phố Đà Nẵng", 75,"Tỉnh Đồng Nai", 38,"Tỉnh Thanh Hoá", 82,"Tỉnh Tiền Giang", 74,"Tỉnh Bình Dương", 49,"Tỉnh Quảng Nam", 51,"Tỉnh Quảng Ngãi", 52,"Tỉnh Bình Định", 40,"Tỉnh Nghệ An", "Không xác định" )} -> Tỉnh Bắc Ninh | AD17: =ROUND((D17/C17)*100, 2) & "%" -> 58.89% | AE17: 1b8b71416fcbbe899d500195ec3934c0 | AF17: =INT(E17) -> 45916 | AG17: =_xlfn.XLOOKUP(AE17, Dev!$A:$A, Dev!$B:$B, "") -> 45748.821 | AH17: =AF17-AG17 -> 167.17903
A18: 16 | B18: ae5ac20156c0be899d5001996279d16c | C18: 1086236 | D18: 551057 | E18: 45919 | G18: Phòng khám Đa khoa Quốc tế Thu Cúc cơ sở Trần Duy Hưng | H18: viêm họng, viêm amidan, viêm phế quan, nhiễm khuẩn nặng | I18: SMART | J18: 45919.924 | K18: =MONTH(J18) -> 9 | L18: 2025 | M18: 2025 | N18: 2025 | O18: 2025 | P18: REIMBURSEMENT_CLAIM | Q18: API | R18: 45598 | S18: 0 | T18: CHILDREN | U18: MALE | V18: OUTPATIENT | W18: Viêm họng, viêm amidan, viêm phế quan, nhiễm khuẩn nặng | X18: Hô hấp | Y18: 0-17 | Z18: =IF(S18<=6,"0-6", IF(S18<=17,"7-17", IF(S18<=35,"18-35", IF(S18<=55,"36-55", "56+")))) -> 0-6 | AA18: 87ee5bfa54ccbe899d50019521552f30 | AB18: 1 | AC18: {=_xlfn.SWITCH(AB18, 79,"Thành phố Hồ Chí Minh", 1,"Thành phố Hà Nội", 35,"Tỉnh Hà Nam", 31,"Thành phố Hải Phòng", 27,"Tỉnh Bắc Ninh", 77,"Tỉnh Bà Rịa - Vũng Tàu", 48,"Thành phố Đà Nẵng", 75,"Tỉnh Đồng Nai", 38,"Tỉnh Thanh Hoá", 82,"Tỉnh Tiền Giang", 74,"Tỉnh Bình Dương", 49,"Tỉnh Quảng Nam", 51,"Tỉnh Quảng Ngãi", 52,"Tỉnh Bình Định", 40,"Tỉnh Nghệ An", "Không xác định" )} -> Thành phố Hà Nội | AD18: =ROUND((D18/C18)*100, 2) & "%" -> 50.73% | AE18: e057c0f954ccbe899d50019521552e55 | AF18: =INT(E18) -> 45919 | AG18: =_xlfn.XLOOKUP(AE18, Dev!$A:$A, Dev!$B:$B, "") -> 45709.423 | AH18: =AF18-AG18 -> 209.57652
A19: 17 | B19: 16c8b8b256c0be899d50019962521b32 | C19: 1499450 | D19: 1399450 | E19: 45916 | F19: 45916 | G19: Bệnh viện Nhi Trung ương - Trung tâm Quốc tế | H19: Viêm mũi họng cấp | I19: SMART | J19: 45919.89 | K19: =MONTH(J19) -> 9 | L19: 2025 | M19: 2025 | N19: 2025 | O19: 2025 | P19: REIMBURSEMENT_CLAIM | Q19: API | R19: 45145 | S19: 2 | T19: CHILDREN | U19: MALE | V19: OUTPATIENT | W19: Viêm mũi họng cấp | X19: Hô hấp | Y19: 0-17 | Z19: =IF(S19<=6,"0-6", IF(S19<=17,"7-17", IF(S19<=35,"18-35", IF(S19<=55,"36-55", "56+")))) -> 0-6 | AA19: 05e1b2f96fcbbe899d500196a384aa24 | AB19: 27 | AC19: {=_xlfn.SWITCH(AB19, 79,"Thành phố Hồ Chí Minh", 1,"Thành phố Hà Nội", 35,"Tỉnh Hà Nam", 31,"Thành phố Hải Phòng", 27,"Tỉnh Bắc Ninh", 77,"Tỉnh Bà Rịa - Vũng Tàu", 48,"Thành phố Đà Nẵng", 75,"Tỉnh Đồng Nai", 38,"Tỉnh Thanh Hoá", 82,"Tỉnh Tiền Giang", 74,"Tỉnh Bình Dương", 49,"Tỉnh Quảng Nam", 51,"Tỉnh Quảng Ngãi", 52,"Tỉnh Bình Định", 40,"Tỉnh Nghệ An", "Không xác định" )} -> Tỉnh Bắc Ninh | AD19: =ROUND((D19/C19)*100, 2) & "%" -> 93.33% | AE19: b91665f96fcbbe899d500196a384aa10 | AF19: =INT(E19) -> 45916 | AG19: =_xlfn.XLOOKUP(AE19, Dev!$A:$A, Dev!$B:$B, "") -> 45784.413 | AH19: =AF19-AG19 -> 131.58669
A20: 18 | B20: 6cd741a756c0be899d500199625067bc | C20: 525000 | D20: 600000 | E20: 45913 | F20: 45913 | G20: Khác | H20: dị ứng nổi mảng đỏ | I20: SMART | J20: 45919.887 | K20: =MONTH(J20) -> 9 | L20: 2025 | M20: 2025 | N20: 2025 | O20: 2025 | P20: REIMBURSEMENT_CLAIM | Q20: API | R20: 45719 | S20: 0 | T20: CHILDREN | U20: MALE | V20: OUTPATIENT | W20: Dị ứng nổi mảng đỏ | X20: Da liễu | Y20: 0-17 | Z20: =IF(S20<=6,"0-6", IF(S20<=17,"7-17", IF(S20<=35,"18-35", IF(S20<=55,"36-55", "56+")))) -> 0-6 | AA20: f94258d56fcbbe899d50019652e38cb4 | AB20: 79 | AC20: {=_xlfn.SWITCH(AB20, 79,"Thành phố Hồ Chí Minh", 1,"Thành phố Hà Nội", 35,"Tỉnh Hà Nam", 31,"Thành phố Hải Phòng", 27,"Tỉnh Bắc Ninh", 77,"Tỉnh Bà Rịa - Vũng Tàu", 48,"Thành phố Đà Nẵng", 75,"Tỉnh Đồng Nai", 38,"Tỉnh Thanh Hoá", 82,"Tỉnh Tiền Giang", 74,"Tỉnh Bình Dương", 49,"Tỉnh Quảng Nam", 51,"Tỉnh Quảng Ngãi", 52,"Tỉnh Bình Định", 40,"Tỉnh Nghệ An", "Không xác định" )} -> Thành phố Hồ Chí Minh | AD20: =ROUND((D20/C20)*100, 2) & "%" -> 114.29% | AE20: 53babd546fcbbe899d50019652e38bf6 | AF20: =INT(E20) -> 45913 | AG20: =_xlfn.XLOOKUP(AE20, Dev!$A:$A, Dev!$B:$B, "") -> 45768.757 | AH20: =AF20-AG20 -> 144.24337
A21: 19 | B21: 36819e35620cbe899d5001995cf4bb7f | C21: 1494700 | D21: 1928890 | E21: 45901 | F21: 45909 | G21: Bệnh viện Nhi Trung ương - Trung tâm Quốc tế | H21: viêm phổi | I21: SMART | J21: 45918.849 | K21: =MONTH(J21) -> 9 | L21: 2025 | M21: 2025 | N21: 2025 | O21: 2025 | P21: REIMBURSEMENT_CLAIM | Q21: API | R21: 45598 | S21: 0 | T21: CHILDREN | U21: MALE | V21: OUTPATIENT | W21: Viêm phổi | X21: Khác | Y21: 0-17 | Z21: =IF(S21<=6,"0-6", IF(S21<=17,"7-17", IF(S21<=35,"18-35", IF(S21<=55,"36-55", "56+")))) -> 0-6 | AA21: 87ee5bfa54ccbe899d50019521552f30 | AB21: 1 | AC21: {=_xlfn.SWITCH(AB21, 79,"Thành phố Hồ Chí Minh", 1,"Thành phố Hà Nội", 35,"Tỉnh Hà Nam", 31,"Thành phố Hải Phòng", 27,"Tỉnh Bắc Ninh", 77,"Tỉnh Bà Rịa - Vũng Tàu", 48,"Thành phố Đà Nẵng", 75,"Tỉnh Đồng Nai", 38,"Tỉnh Thanh Hoá", 82,"Tỉnh Tiền Giang", 74,"Tỉnh Bình Dương", 49,"Tỉnh Quảng Nam", 51,"Tỉnh Quảng Ngãi", 52,"Tỉnh Bình Định", 40,"Tỉnh Nghệ An", "Không xác định" )} -> Thành phố Hà Nội | AD21: =ROUND((D21/C21)*100, 2) & "%" -> 129.05% | AE21: e057c0f954ccbe899d50019521552e55 | AF21: =INT(E21) -> 45901 | AG21: =_xlfn.XLOOKUP(AE21, Dev!$A:$A, Dev!$B:$B, "") -> 45709.423 | AH21: =AF21-AG21 -> 191.57652
A22: 20 | B22: 71807efc620cbe899d5001995c69d23c | C22: 742600 | D22: 742600 | E22: 45902 | F22: 45902 | G22: Bệnh viện Nhi Trung ương - Trung tâm Quốc tế | H22: Viêm mũi họng cấp | I22: SMART | J22: 45918.739 | K22: =MONTH(J22) -> 9 | L22: 2025 | M22: 2025 | N22: 2025 | O22: 2025 | P22: REIMBURSEMENT_CLAIM | Q22: API | R22: 45381 | S22: 1 | T22: CHILDREN | U22: FEMALE | V22: OUTPATIENT | W22: Viêm mũi họng cấp | X22: Hô hấp | Y22: 0-17 | Z22: =IF(S22<=6,"0-6", IF(S22<=17,"7-17", IF(S22<=35,"18-35", IF(S22<=55,"36-55", "56+")))) -> 0-6 | AA22: a35827ff1eecbe899d5001951229a4b9 | AB22: 1 | AC22: {=_xlfn.SWITCH(AB22, 79,"Thành phố Hồ Chí Minh", 1,"Thành phố Hà Nội", 35,"Tỉnh Hà Nam", 31,"Thành phố Hải Phòng", 27,"Tỉnh Bắc Ninh", 77,"Tỉnh Bà Rịa - Vũng Tàu", 48,"Thành phố Đà Nẵng", 75,"Tỉnh Đồng Nai", 38,"Tỉnh Thanh Hoá", 82,"Tỉnh Tiền Giang", 74,"Tỉnh Bình Dương", 49,"Tỉnh Quảng Nam", 51,"Tỉnh Quảng Ngãi", 52,"Tỉnh Bình Định", 40,"Tỉnh Nghệ An", "Không xác định" )} -> Thành phố Hà Nội | AD22: =ROUND((D22/C22)*100, 2) & "%" -> 100% | AE22: 0db09cfe1eecbe899d5001951229a40c | AF22: =INT(E22) -> 45902 | AG22: =_xlfn.XLOOKUP(AE22, Dev!$A:$A, Dev!$B:$B, "") -> 45706.478 | AH22: =AF22-AG22 -> 195.52226
A23: 21 | B23: 237d3c222223be899d500199578fab83 | C23: 414000 | D23: 331200 | E23: 45916 | F23: 45916 | G23: Cty Cổ phần Phòng Khám Đa Khoa Y Sài Gòn | H23: viêm họng cấp | I23: SMART | J23: 45917.797 | K23: =MONTH(J23) -> 9 | L23: 2025 | M23: 2025 | N23: 2025 | O23: 2025 | P23: REIMBURSEMENT_CLAIM | Q23: API | R23: 45330 | S23: 1 | T23: CHILDREN | U23: FEMALE | V23: OUTPATIENT | W23: Viêm họng cấp | X23: Hô hấp | Y23: 0-17 | Z23: =IF(S23<=6,"0-6", IF(S23<=17,"7-17", IF(S23<=35,"18-35", IF(S23<=55,"36-55", "56+")))) -> 0-6 | AA23: 769306fa75c8be899d5001954b3db504 | AB23: 77 | AC23: {=_xlfn.SWITCH(AB23, 79,"Thành phố Hồ Chí Minh", 1,"Thành phố Hà Nội", 35,"Tỉnh Hà Nam", 31,"Thành phố Hải Phòng", 27,"Tỉnh Bắc Ninh", 77,"Tỉnh Bà Rịa - Vũng Tàu", 48,"Thành phố Đà Nẵng", 75,"Tỉnh Đồng Nai", 38,"Tỉnh Thanh Hoá", 82,"Tỉnh Tiền Giang", 74,"Tỉnh Bình Dương", 49,"Tỉnh Quảng Nam", 51,"Tỉnh Quảng Ngãi", 52,"Tỉnh Bình Định", 40,"Tỉnh Nghệ An", "Không xác định" )} -> Tỉnh Bà Rịa - Vũng Tàu | AD23: =ROUND((D23/C23)*100, 2) & "%" -> 80% | AE23: dffb6bf875c8be899d5001954b3db456 | AF23: =INT(E23) -> 45916 | AG23: =_xlfn.XLOOKUP(AE23, Dev!$A:$A, Dev!$B:$B, "") -> 45717.561 | AH23: =AF23-AG23 -> 198.43874
A24: 22 | B24: 4e48e2fd2223be899d50019955db8f9d | C24: 865000 | D24: 532000 | E24: 45911 | F24: 45911 | G24: KHÁC | H24: viêm mũi họng/ trào ngược dạ dày thực quản | I24: SMART | J24: 45917.473 | K24: =MONTH(J24) -> 9 | L24: 2025 | M24: 2025 | N24: 2025 | O24: 2025 | P24: REIMBURSEMENT_CLAIM | Q24: API | R24: 45454 | S24: 1 | T24: CHILDREN | U24: MALE | V24: OUTPATIENT | W24: Viêm mũi họng/ trào ngược dạ dày thực quản | X24: Hô hấp | Y24: 0-17 | Z24: =IF(S24<=6,"0-6", IF(S24<=17,"7-17", IF(S24<=35,"18-35", IF(S24<=55,"36-55", "56+")))) -> 0-6 | AA24: fb9ba0016fcbbe899d500195d178a84f | AB24: 1 | AC24: {=_xlfn.SWITCH(AB24, 79,"Thành phố Hồ Chí Minh", 1,"Thành phố Hà Nội", 35,"Tỉnh Hà Nam", 31,"Thành phố Hải Phòng", 27,"Tỉnh Bắc Ninh", 77,"Tỉnh Bà Rịa - Vũng Tàu", 48,"Thành phố Đà Nẵng", 75,"Tỉnh Đồng Nai", 38,"Tỉnh Thanh Hoá", 82,"Tỉnh Tiền Giang", 74,"Tỉnh Bình Dương", 49,"Tỉnh Quảng Nam", 51,"Tỉnh Quảng Ngãi", 52,"Tỉnh Bình Định", 40,"Tỉnh Nghệ An", "Không xác định" )} -> Thành phố Hà Nội | AD24: =ROUND((D24/C24)*100, 2) & "%" -> 61.5% | AE24: 550416ff6fcbbe899d500195d178a774 | AF24: =INT(E24) -> 45911 | AG24: =_xlfn.XLOOKUP(AE24, Dev!$A:$A, Dev!$B:$B, "") -> 45745.37 | AH24: =AF24-AG24 -> 165.62973
A25: 23 | B25: 0412eefd2223be899d50019955e0dd05 | C25: 824538 | D25: 824538 | E25: 45913 | G25: Bệnh viện Nhi Trung ương | H25: Viêm tai ngoài | I25: SMART | J25: 45917.472 | K25: =MONTH(J25) -> 9 | L25: 2025 | M25: 2025 | N25: 2025 | O25: 2025 | P25: REIMBURSEMENT_CLAIM | Q25: API | R25: 45713 | S25: 0 | T25: CHILDREN | U25: FEMALE | V25: INPATIENT | W25: Viêm tai ngoài | X25: Khác | Y25: 0-17 | Z25: =IF(S25<=6,"0-6", IF(S25<=17,"7-17", IF(S25<=35,"18-35", IF(S25<=55,"36-55", "56+")))) -> 0-6 | AA25: 2dd6adf86fcbbe899d500195dc559f2c | AB25: 1 | AC25: {=_xlfn.SWITCH(AB25, 79,"Thành phố Hồ Chí Minh", 1,"Thành phố Hà Nội", 35,"Tỉnh Hà Nam", 31,"Thành phố Hải Phòng", 27,"Tỉnh Bắc Ninh", 77,"Tỉnh Bà Rịa - Vũng Tàu", 48,"Thành phố Đà Nẵng", 75,"Tỉnh Đồng Nai", 38,"Tỉnh Thanh Hoá", 82,"Tỉnh Tiền Giang", 74,"Tỉnh Bình Dương", 49,"Tỉnh Quảng Nam", 51,"Tỉnh Quảng Ngãi", 52,"Tỉnh Bình Định", 40,"Tỉnh Nghệ An", "Không xác định" )} -> Thành phố Hà Nội | AD25: =ROUND((D25/C25)*100, 2) & "%" -> 100% | AE25: 864f03c66fcbbe899d500195dc559e7b | AF25: =INT(E25) -> 45913 | AG25: =_xlfn.XLOOKUP(AE25, Dev!$A:$A, Dev!$B:$B, "") -> 45745.736 | AH25: =AF25-AG25 -> 167.26437
A26: 24 | B26: 5c5c00f82223be899d50019955b58a86 | C26: 970700 | D26: 722000 | E26: 45917 | G26: Bệnh viện Nhi Trung ương - Trung tâm Quốc tế | H26: Viêm mũi họng - Viêm amidan mủ | I26: SMART | J26: 45917.442 | K26: =MONTH(J26) -> 9 | L26: 2025 | M26: 2025 | N26: 2025 | O26: 2025 | P26: REIMBURSEMENT_CLAIM | Q26: API | R26: 45266 | S26: 1 | T26: CHILDREN | U26: MALE | V26: OUTPATIENT | W26: Viêm mũi họng - viêm amidan mủ | X26: Hô hấp | Y26: 0-17 | Z26: =IF(S26<=6,"0-6", IF(S26<=17,"7-17", IF(S26<=35,"18-35", IF(S26<=55,"36-55", "56+")))) -> 0-6 | AA26: 1296ce307a1bbe899d50019734e1043b | AB26: 1 | AC26: {=_xlfn.SWITCH(AB26, 79,"Thành phố Hồ Chí Minh", 1,"Thành phố Hà Nội", 35,"Tỉnh Hà Nam", 31,"Thành phố Hải Phòng", 27,"Tỉnh Bắc Ninh", 77,"Tỉnh Bà Rịa - Vũng Tàu", 48,"Thành phố Đà Nẵng", 75,"Tỉnh Đồng Nai", 38,"Tỉnh Thanh Hoá", 82,"Tỉnh Tiền Giang", 74,"Tỉnh Bình Dương", 49,"Tỉnh Quảng Nam", 51,"Tỉnh Quảng Ngãi", 52,"Tỉnh Bình Định", 40,"Tỉnh Nghệ An", "Không xác định" )} -> Thành phố Hà Nội | AD26: =ROUND((D26/C26)*100, 2) & "%" -> 74.38% | AE26: 7bfe24fe7a1bbe899d50019734e1036c | AF26: =INT(E26) -> 45917 | AG26: =_xlfn.XLOOKUP(AE26, Dev!$A:$A, Dev!$B:$B, "") -> 45812.64 | AH26: =AF26-AG26 -> 104.36043
A27: 25 | B27: b9b3a1c62223be899d5001995593cdef | C27: 340360 | D27: 272287 | E27: 45910 | F27: 45910 | G27: Bệnh viện Đa khoa Tâm Anh Hồ Chí Minh | H27: Nhiễm trùng đường hô hấp trên cấp | I27: SMART | J27: 45917.413 | K27: =MONTH(J27) -> 9 | L27: 2025 | M27: 2025 | N27: 2025 | O27: 2025 | P27: REIMBURSEMENT_CLAIM | Q27: API | R27: 44634 | S27: 3 | T27: CHILDREN | U27: FEMALE | V27: OUTPATIENT | W27: Nhiễm trùng đường hô hấp trên cấp | X27: Hô hấp | Y27: 0-17 | Z27: =IF(S27<=6,"0-6", IF(S27<=17,"7-17", IF(S27<=35,"18-35", IF(S27<=55,"36-55", "56+")))) -> 0-6 | AA27: 389a40fa6fcbbe899d500195effc1e6e | AB27: 79 | AC27: {=_xlfn.SWITCH(AB27, 79,"Thành phố Hồ Chí Minh", 1,"Thành phố Hà Nội", 35,"Tỉnh Hà Nam", 31,"Thành phố Hải Phòng", 27,"Tỉnh Bắc Ninh", 77,"Tỉnh Bà Rịa - Vũng Tàu", 48,"Thành phố Đà Nẵng", 75,"Tỉnh Đồng Nai", 38,"Tỉnh Thanh Hoá", 82,"Tỉnh Tiền Giang", 74,"Tỉnh Bình Dương", 49,"Tỉnh Quảng Nam", 51,"Tỉnh Quảng Ngãi", 52,"Tỉnh Bình Định", 40,"Tỉnh Nghệ An", "Không xác định" )} -> Thành phố Hồ Chí Minh | AD27: =ROUND((D27/C27)*100, 2) & "%" -> 80% | AE27: 9103b5f96fcbbe899d500195effc1db7 | AF27: =INT(E27) -> 45910 | AG27: =_xlfn.XLOOKUP(AE27, Dev!$A:$A, Dev!$B:$B, "") -> 45749.551 | AH27: =AF27-AG27 -> 160.44865
A28: 26 | B28: 147855fc682bbe899d5001994cb5f12f | C28: 1044000 | D28: 193000 | E28: 45915 | F28: 45915 | G28: Khác | H28: Ban đỏ CTNN, TD tay chân miệng độ I | I28: SMART | J28: 45915.691 | K28: =MONTH(J28) -> 9 | L28: 2025 | M28: 2025 | N28: 2025 | O28: 2025 | P28: REIMBURSEMENT_CLAIM | Q28: API | R28: 45650 | S28: 0 | T28: CHILDREN | U28: MALE | V28: OUTPATIENT | W28: Ban đỏ ctnn, td tay chân miệng độ i | X28: Khác | Y28: 0-17 | Z28: =IF(S28<=6,"0-6", IF(S28<=17,"7-17", IF(S28<=35,"18-35", IF(S28<=55,"36-55", "56+")))) -> 0-6 | AA28: 82097e071eecbe899d500194f39980eb | AB28: 31 | AC28: {=_xlfn.SWITCH(AB28, 79,"Thành phố Hồ Chí Minh", 1,"Thành phố Hà Nội", 35,"Tỉnh Hà Nam", 31,"Thành phố Hải Phòng", 27,"Tỉnh Bắc Ninh", 77,"Tỉnh Bà Rịa - Vũng Tàu", 48,"Thành phố Đà Nẵng", 75,"Tỉnh Đồng Nai", 38,"Tỉnh Thanh Hoá", 82,"Tỉnh Tiền Giang", 74,"Tỉnh Bình Dương", 49,"Tỉnh Quảng Nam", 51,"Tỉnh Quảng Ngãi", 52,"Tỉnh Bình Định", 40,"Tỉnh Nghệ An", "Không xác định" )} -> Thành phố Hải Phòng | AD28: =ROUND((D28/C28)*100, 2) & "%" -> 18.49% | AE28: 373d21561eecbe899d500194f39980db | AF28: =INT(E28) -> 45915 | AG28: =_xlfn.XLOOKUP(AE28, Dev!$A:$A, Dev!$B:$B, "") -> 45700.543 | AH28: =AF28-AG28 -> 214.45703
A29: 27 | B29: 065b56841924be899d5001994775dc64 | C29: 783750 | D29: 783750 | E29: 45914 | G29: Bệnh viện Nhi Trung ương - Trung tâm Quốc tế | H29: Viêm phế quản cấp (Viêm mũi họng) | I29: SMART | J29: 45914.673 | K29: =MONTH(J29) -> 9 | L29: 2025 | M29: 2025 | N29: 2025 | O29: 2025 | P29: REIMBURSEMENT_CLAIM | Q29: API | R29: 45283 | S29: 1 | T29: CHILDREN | U29: MALE | V29: OUTPATIENT | W29: Viêm phế quản cấp (viêm mũi họng) | X29: Hô hấp | Y29: 0-17 | Z29: =IF(S29<=6,"0-6", IF(S29<=17,"7-17", IF(S29<=35,"18-35", IF(S29<=55,"36-55", "56+")))) -> 0-6 | AA29: 3ecf7efb75c8be899d5001956abd408b | AB29: 35 | AC29: {=_xlfn.SWITCH(AB29, 79,"Thành phố Hồ Chí Minh", 1,"Thành phố Hà Nội", 35,"Tỉnh Hà Nam", 31,"Thành phố Hải Phòng", 27,"Tỉnh Bắc Ninh", 77,"Tỉnh Bà Rịa - Vũng Tàu", 48,"Thành phố Đà Nẵng", 75,"Tỉnh Đồng Nai", 38,"Tỉnh Thanh Hoá", 82,"Tỉnh Tiền Giang", 74,"Tỉnh Bình Dương", 49,"Tỉnh Quảng Nam", 51,"Tỉnh Quảng Ngãi", 52,"Tỉnh Bình Định", 40,"Tỉnh Nghệ An", "Không xác định" )} -> Tỉnh Hà Nam | AD29: =ROUND((D29/C29)*100, 2) & "%" -> 100% | AE29: 9738e3f975c8be899d5001956abd3fd9 | AF29: =INT(E29) -> 45914 | AG29: =_xlfn.XLOOKUP(AE29, Dev!$A:$A, Dev!$B:$B, "") -> 45723.678 | AH29: =AF29-AG29 -> 190.32238
A30: 28 | B30: 03b844fa1924be899d500199462bba4b | C30: 550975 | D30: 550975 | E30: 45913 | F30: 45913 | G30: Bệnh viện Phụ sản - Nhi Đà Nẵng | H30: viêm ruột, viêm tai giữa | I30: SMART | J30: 45914.424 | K30: =MONTH(J30) -> 9 | L30: 2025 | M30: 2025 | N30: 2025 | O30: 2025 | P30: REIMBURSEMENT_CLAIM | Q30: API | R30: 45650 | S30: 0 | T30: CHILDREN | U30: FEMALE | V30: OUTPATIENT | W30: Viêm ruột, viêm tai giữa | X30: Tiêu hóa | Y30: 0-17 | Z30: =IF(S30<=6,"0-6", IF(S30<=17,"7-17", IF(S30<=35,"18-35", IF(S30<=55,"36-55", "56+")))) -> 0-6 | AA30: 3cce602175c8be899d5001954f974cbe | AB30: 48 | AC30: {=_xlfn.SWITCH(AB30, 79,"Thành phố Hồ Chí Minh", 1,"Thành phố Hà Nội", 35,"Tỉnh Hà Nam", 31,"Thành phố Hải Phòng", 27,"Tỉnh Bắc Ninh", 77,"Tỉnh Bà Rịa - Vũng Tàu", 48,"Thành phố Đà Nẵng", 75,"Tỉnh Đồng Nai", 38,"Tỉnh Thanh Hoá", 82,"Tỉnh Tiền Giang", 74,"Tỉnh Bình Dương", 49,"Tỉnh Quảng Nam", 51,"Tỉnh Quảng Ngãi", 52,"Tỉnh Bình Định", 40,"Tỉnh Nghệ An", "Không xác định" )} -> Thành phố Đà Nẵng | AD30: =ROUND((D30/C30)*100, 2) & "%" -> 100% | AE30: 9537d5ff75c8be899d5001954f974bf8 | AF30: =INT(E30) -> 45913 | AG30: =_xlfn.XLOOKUP(AE30, Dev!$A:$A, Dev!$B:$B, "") -> 45718.406 | AH30: =AF30-AG30 -> 194.59405
A31: 29 | B31: 04adb8fc604abe899d5001993cb21cfb | C31: 419471 | D31: 419471 | E31: 45905 | F31: 45905 | G31: Bệnh viện Nhi Đồng I | H31: Viêm mũi họng | I31: SMART | J31: 45912.581 | K31: =MONTH(J31) -> 9 | L31: 2025 | M31: 2025 | N31: 2025 | O31: 2025 | P31: REIMBURSEMENT_CLAIM | Q31: API | R31: 44269 | S31: 4 | T31: CHILDREN | U31: MALE | V31: OUTPATIENT | W31: Viêm mũi họng | X31: Hô hấp | Y31: 0-17 | Z31: =IF(S31<=6,"0-6", IF(S31<=17,"7-17", IF(S31<=35,"18-35", IF(S31<=55,"36-55", "56+")))) -> 0-6 | AA31: e7056dfc7b61be899d500195376d0bdf | AB31: 79 | AC31: {=_xlfn.SWITCH(AB31, 79,"Thành phố Hồ Chí Minh", 1,"Thành phố Hà Nội", 35,"Tỉnh Hà Nam", 31,"Thành phố Hải Phòng", 27,"Tỉnh Bắc Ninh", 77,"Tỉnh Bà Rịa - Vũng Tàu", 48,"Thành phố Đà Nẵng", 75,"Tỉnh Đồng Nai", 38,"Tỉnh Thanh Hoá", 82,"Tỉnh Tiền Giang", 74,"Tỉnh Bình Dương", 49,"Tỉnh Quảng Nam", 51,"Tỉnh Quảng Ngãi", 52,"Tỉnh Bình Định", 40,"Tỉnh Nghệ An", "Không xác định" )} -> Thành phố Hồ Chí Minh | AD31: =ROUND((D31/C31)*100, 2) & "%" -> 100% | AE31: 9c3910fb7b61be899d500195376d0bcd | AF31: =INT(E31) -> 45905 | AG31: =_xlfn.XLOOKUP(AE31, Dev!$A:$A, Dev!$B:$B, "") -> 45689 | AH31: =AF31-AG31 -> 216
A32: 30 | B32: 37b7fca3604abe899d5001993cad7cf3 | C32: 398499 | D32: 398499 | E32: 45903 | F32: 45903 | G32: Bệnh viện Nhi Đồng I | H32: Viêm mũi họng | I32: SMART | J32: 45912.578 | K32: =MONTH(J32) -> 9 | L32: 2025 | M32: 2025 | N32: 2025 | O32: 2025 | P32: REIMBURSEMENT_CLAIM | Q32: API | R32: 44269 | S32: 4 | T32: CHILDREN | U32: MALE | V32: OUTPATIENT | W32: Viêm mũi họng | X32: Hô hấp | Y32: 0-17 | Z32: =IF(S32<=6,"0-6", IF(S32<=17,"7-17", IF(S32<=35,"18-35", IF(S32<=55,"36-55", "56+")))) -> 0-6 | AA32: e7056dfc7b61be899d500195376d0bdf | AB32: 79 | AC32: {=_xlfn.SWITCH(AB32, 79,"Thành phố Hồ Chí Minh", 1,"Thành phố Hà Nội", 35,"Tỉnh Hà Nam", 31,"Thành phố Hải Phòng", 27,"Tỉnh Bắc Ninh", 77,"Tỉnh Bà Rịa - Vũng Tàu", 48,"Thành phố Đà Nẵng", 75,"Tỉnh Đồng Nai", 38,"Tỉnh Thanh Hoá", 82,"Tỉnh Tiền Giang", 74,"Tỉnh Bình Dương", 49,"Tỉnh Quảng Nam", 51,"Tỉnh Quảng Ngãi", 52,"Tỉnh Bình Định", 40,"Tỉnh Nghệ An", "Không xác định" )} -> Thành phố Hồ Chí Minh | AD32: =ROUND((D32/C32)*100, 2) & "%" -> 100% | AE32: 9c3910fb7b61be899d500195376d0bcd | AF32: =INT(E32) -> 45903 | AG32: =_xlfn.XLOOKUP(AE32, Dev!$A:$A, Dev!$B:$B, "") -> 45689 | AH32: =AF32-AG32 -> 214
A33: 31 | B33: feb6a9fe25aebe899d50019936e3017e | C33: 1919500 | D33: 715500 | E33: 45907 | F33: 45911 | G33: Bệnh viện Đa khoa Hồng Ngọc - Phúc Trường Minh | H33: K90.1 | I33: SMART | J33: 45911.451 | K33: =MONTH(J33) -> 9 | L33: 2025 | M33: 2025 | N33: 2025 | O33: 2025 | P33: REIMBURSEMENT_CLAIM | Q33: API | R33: 45619 | S33: 0 | T33: CHILDREN | U33: FEMALE | V33: OUTPATIENT | W33: K90.1 | X33: Khác | Y33: 0-17 | Z33: =IF(S33<=6,"0-6", IF(S33<=17,"7-17", IF(S33<=35,"18-35", IF(S33<=55,"36-55", "56+")))) -> 0-6 | AA33: 776ac0c37a13be899d5001948d5f03c1 | AB33: 1 | AC33: {=_xlfn.SWITCH(AB33, 79,"Thành phố Hồ Chí Minh", 1,"Thành phố Hà Nội", 35,"Tỉnh Hà Nam", 31,"Thành phố Hải Phòng", 27,"Tỉnh Bắc Ninh", 77,"Tỉnh Bà Rịa - Vũng Tàu", 48,"Thành phố Đà Nẵng", 75,"Tỉnh Đồng Nai", 38,"Tỉnh Thanh Hoá", 82,"Tỉnh Tiền Giang", 74,"Tỉnh Bình Dương", 49,"Tỉnh Quảng Nam", 51,"Tỉnh Quảng Ngãi", 52,"Tỉnh Bình Định", 40,"Tỉnh Nghệ An", "Không xác định" )} -> Thành phố Hà Nội | AD33: =ROUND((D33/C33)*100, 2) & "%" -> 37.28% | AE33: d0d236427a13be899d5001948d5f0310 | AF33: =INT(E33) -> 45907 | AG33: =_xlfn.XLOOKUP(AE33, Dev!$A:$A, Dev!$B:$B, "") -> 45680.692 | AH33: =AF33-AG33 -> 226.30782
A34: 32 | B34: b83724c71b9bbe899d5001992d5c9ba8 | C34: 172000 | D34: 137600 | E34: 45900 | F34: 45900 | G34: Hệ thống Phòng khám Nhi Đồng 315 - PK 16 | H34: Viêm mũi họng cấp bội nhiễm. Viêm mũi dị ứng | I34: SMART | J34: 45909.603 | K34: =MONTH(J34) -> 9 | L34: 2025 | M34: 2025 | N34: 2025 | O34: 2025 | P34: REIMBURSEMENT_CLAIM | Q34: API | R34: 44269 | S34: 4 | T34: CHILDREN | U34: MALE | V34: OUTPATIENT | W34: Viêm mũi họng cấp bội nhiễm. viêm mũi dị ứng | X34: Hô hấp | Y34: 0-17 | Z34: =IF(S34<=6,"0-6", IF(S34<=17,"7-17", IF(S34<=35,"18-35", IF(S34<=55,"36-55", "56+")))) -> 0-6 | AA34: e7056dfc7b61be899d500195376d0bdf | AB34: 79 | AC34: {=_xlfn.SWITCH(AB34, 79,"Thành phố Hồ Chí Minh", 1,"Thành phố Hà Nội", 35,"Tỉnh Hà Nam", 31,"Thành phố Hải Phòng", 27,"Tỉnh Bắc Ninh", 77,"Tỉnh Bà Rịa - Vũng Tàu", 48,"Thành phố Đà Nẵng", 75,"Tỉnh Đồng Nai", 38,"Tỉnh Thanh Hoá", 82,"Tỉnh Tiền Giang", 74,"Tỉnh Bình Dương", 49,"Tỉnh Quảng Nam", 51,"Tỉnh Quảng Ngãi", 52,"Tỉnh Bình Định", 40,"Tỉnh Nghệ An", "Không xác định" )} -> Thành phố Hồ Chí Minh | AD34: =ROUND((D34/C34)*100, 2) & "%" -> 80% | AE34: 9c3910fb7b61be899d500195376d0bcd | AF34: =INT(E34) -> 45900 | AG34: =_xlfn.XLOOKUP(AE34, Dev!$A:$A, Dev!$B:$B, "") -> 45689 | AH34: =AF34-AG34 -> 211
A35: 33 | B35: a11b54fe1b9bbe899d5001992d58140b | C35: 104000 | D35: 83200 | E35: 45898 | F35: 45898 | G35: Hệ thống Phòng khám Nhi Đồng 315 - PK 16 | H35: Viêm mũi họng cấp [cảm thường] bội nhiễm | I35: SMART | J35: 45909.6 | K35: =MONTH(J35) -> 9 | L35: 2025 | M35: 2025 | N35: 2025 | O35: 2025 | P35: REIMBURSEMENT_CLAIM | Q35: API | R35: 44269 | S35: 4 | T35: CHILDREN | U35: MALE | V35: OUTPATIENT | W35: Viêm mũi họng cấp [cảm thường] bội nhiễm | X35: Hô hấp | Y35: 0-17 | Z35: =IF(S35<=6,"0-6", IF(S35<=17,"7-17", IF(S35<=35,"18-35", IF(S35<=55,"36-55", "56+")))) -> 0-6 | AA35: e7056dfc7b61be899d500195376d0bdf | AB35: 79 | AC35: {=_xlfn.SWITCH(AB35, 79,"Thành phố Hồ Chí Minh", 1,"Thành phố Hà Nội", 35,"Tỉnh Hà Nam", 31,"Thành phố Hải Phòng", 27,"Tỉnh Bắc Ninh", 77,"Tỉnh Bà Rịa - Vũng Tàu", 48,"Thành phố Đà Nẵng", 75,"Tỉnh Đồng Nai", 38,"Tỉnh Thanh Hoá", 82,"Tỉnh Tiền Giang", 74,"Tỉnh Bình Dương", 49,"Tỉnh Quảng Nam", 51,"Tỉnh Quảng Ngãi", 52,"Tỉnh Bình Định", 40,"Tỉnh Nghệ An", "Không xác định" )} -> Thành phố Hồ Chí Minh | AD35: =ROUND((D35/C35)*100, 2) & "%" -> 80% | AE35: 9c3910fb7b61be899d500195376d0bcd | AF35: =INT(E35) -> 45898 | AG35: =_xlfn.XLOOKUP(AE35, Dev!$A:$A, Dev!$B:$B, "") -> 45689 | AH35: =AF35-AG35 -> 209
A36: 34 | B36: 23e907f91b9bbe899d5001992d543ff5 | C36: 72000 | D36: 25600 | E36: 45896 | F36: 45896 | G36: Hệ thống Phòng khám Nhi Đồng 315 - PK 16 | H36: Viêm mũi họng cấp [cảm thường] | I36: SMART | J36: 45909.597 | K36: =MONTH(J36) -> 9 | L36: 2025 | M36: 2025 | N36: 2025 | O36: 2025 | P36: REIMBURSEMENT_CLAIM | Q36: API | R36: 44269 | S36: 4 | T36: CHILDREN | U36: MALE | V36: OUTPATIENT | W36: Viêm mũi họng cấp [cảm thường] | X36: Hô hấp | Y36: 0-17 | Z36: =IF(S36<=6,"0-6", IF(S36<=17,"7-17", IF(S36<=35,"18-35", IF(S36<=55,"36-55", "56+")))) -> 0-6 | AA36: e7056dfc7b61be899d500195376d0bdf | AB36: 79 | AC36: {=_xlfn.SWITCH(AB36, 79,"Thành phố Hồ Chí Minh", 1,"Thành phố Hà Nội", 35,"Tỉnh Hà Nam", 31,"Thành phố Hải Phòng", 27,"Tỉnh Bắc Ninh", 77,"Tỉnh Bà Rịa - Vũng Tàu", 48,"Thành phố Đà Nẵng", 75,"Tỉnh Đồng Nai", 38,"Tỉnh Thanh Hoá", 82,"Tỉnh Tiền Giang", 74,"Tỉnh Bình Dương", 49,"Tỉnh Quảng Nam", 51,"Tỉnh Quảng Ngãi", 52,"Tỉnh Bình Định", 40,"Tỉnh Nghệ An", "Không xác định" )} -> Thành phố Hồ Chí Minh | AD36: =ROUND((D36/C36)*100, 2) & "%" -> 35.56% | AE36: 9c3910fb7b61be899d500195376d0bcd | AF36: =INT(E36) -> 45896 | AG36: =_xlfn.XLOOKUP(AE36, Dev!$A:$A, Dev!$B:$B, "") -> 45689 | AH36: =AF36-AG36 -> 207
A37: 35 | B37: 97f563131b9bbe899d5001992d50519e | C37: 288000 | D37: 206400 | E37: 45893 | F37: 45893 | G37: Hệ thống Phòng khám Nhi Đồng 315 - PK 16 | H37: Viêm mũi dị ứng | I37: SMART | J37: 45909.593 | K37: =MONTH(J37) -> 9 | L37: 2025 | M37: 2025 | N37: 2025 | O37: 2025 | P37: REIMBURSEMENT_CLAIM | Q37: API | R37: 44269 | S37: 4 | T37: CHILDREN | U37: MALE | V37: OUTPATIENT | W37: Viêm mũi dị ứng | X37: Hô hấp | Y37: 0-17 | Z37: =IF(S37<=6,"0-6", IF(S37<=17,"7-17", IF(S37<=35,"18-35", IF(S37<=55,"36-55", "56+")))) -> 0-6 | AA37: e7056dfc7b61be899d500195376d0bdf | AB37: 79 | AC37: {=_xlfn.SWITCH(AB37, 79,"Thành phố Hồ Chí Minh", 1,"Thành phố Hà Nội", 35,"Tỉnh Hà Nam", 31,"Thành phố Hải Phòng", 27,"Tỉnh Bắc Ninh", 77,"Tỉnh Bà Rịa - Vũng Tàu", 48,"Thành phố Đà Nẵng", 75,"Tỉnh Đồng Nai", 38,"Tỉnh Thanh Hoá", 82,"Tỉnh Tiền Giang", 74,"Tỉnh Bình Dương", 49,"Tỉnh Quảng Nam", 51,"Tỉnh Quảng Ngãi", 52,"Tỉnh Bình Định", 40,"Tỉnh Nghệ An", "Không xác định" )} -> Thành phố Hồ Chí Minh | AD37: =ROUND((D37/C37)*100, 2) & "%" -> 71.67% | AE37: 9c3910fb7b61be899d500195376d0bcd | AF37: =INT(E37) -> 45893 | AG37: =_xlfn.XLOOKUP(AE37, Dev!$A:$A, Dev!$B:$B, "") -> 45689 | AH37: =AF37-AG37 -> 204
A38: 36 | B38: 2107f5631b9bbe899d50019917fe611d | C38: 1634324 | D38: 578200 | E38: 45897 | G38: Bệnh Viện Nhi Đồng II | H38: viêm phế quản cấp | I38: SMART | J38: 45908.561 | K38: =MONTH(J38) -> 9 | L38: 2025 | M38: 2025 | N38: 2025 | O38: 2025 | P38: REIMBURSEMENT_CLAIM | Q38: API | R38: 45589 | S38: 0 | T38: CHILDREN | U38: MALE | V38: OUTPATIENT | W38: Viêm phế quản cấp | X38: Khác | Y38: 0-17 | Z38: =IF(S38<=6,"0-6", IF(S38<=17,"7-17", IF(S38<=35,"18-35", IF(S38<=55,"36-55", "56+")))) -> 0-6 | AA38: 8c81c1fd7a1bbe899d5001978716e584 | AB38: 79 | AC38: {=_xlfn.SWITCH(AB38, 79,"Thành phố Hồ Chí Minh", 1,"Thành phố Hà Nội", 35,"Tỉnh Hà Nam", 31,"Thành phố Hải Phòng", 27,"Tỉnh Bắc Ninh", 77,"Tỉnh Bà Rịa - Vũng Tàu", 48,"Thành phố Đà Nẵng", 75,"Tỉnh Đồng Nai", 38,"Tỉnh Thanh Hoá", 82,"Tỉnh Tiền Giang", 74,"Tỉnh Bình Dương", 49,"Tỉnh Quảng Nam", 51,"Tỉnh Quảng Ngãi", 52,"Tỉnh Bình Định", 40,"Tỉnh Nghệ An", "Không xác định" )} -> Thành phố Hồ Chí Minh | AD38: =ROUND((D38/C38)*100, 2) & "%" -> 35.38% | AE38: e5f927fb7a1bbe899d5001978716e4c5 | AF38: =INT(E38) -> 45897 | AG38: =_xlfn.XLOOKUP(AE38, Dev!$A:$A, Dev!$B:$B, "") -> 45829.619 | AH38: =AF38-AG38 -> 67.38059
A39: 37 | B39: 20f830e01b9bbe899d5001992791a907 | C39: 514000 | D39: 411200 | E39: 45908 | G39: Phòng khám Happy Baby Biên Hòa | H39: Viêm mũi họng do siêu vi | I39: SMART | J39: 45908.477 | K39: =MONTH(J39) -> 9 | L39: 2025 | M39: 2025 | N39: 2025 | O39: 2025 | P39: REIMBURSEMENT_CLAIM | Q39: API | R39: 45678 | S39: 0 | T39: CHILDREN | U39: MALE | V39: OUTPATIENT | W39: Viêm mũi họng do siêu vi | X39: Hô hấp | Y39: 0-17 | Z39: =IF(S39<=6,"0-6", IF(S39<=17,"7-17", IF(S39<=35,"18-35", IF(S39<=55,"36-55", "56+")))) -> 0-6 | AA39: 8a2131346fcbbe899d500195c2f674a2 | AB39: 75 | AC39: {=_xlfn.SWITCH(AB39, 79,"Thành phố Hồ Chí Minh", 1,"Thành phố Hà Nội", 35,"Tỉnh Hà Nam", 31,"Thành phố Hải Phòng", 27,"Tỉnh Bắc Ninh", 77,"Tỉnh Bà Rịa - Vũng Tàu", 48,"Thành phố Đà Nẵng", 75,"Tỉnh Đồng Nai", 38,"Tỉnh Thanh Hoá", 82,"Tỉnh Tiền Giang", 74,"Tỉnh Bình Dương", 49,"Tỉnh Quảng Nam", 51,"Tỉnh Quảng Ngãi", 52,"Tỉnh Bình Định", 40,"Tỉnh Nghệ An", "Không xác định" )} -> Tỉnh Đồng Nai | AD39: =ROUND((D39/C39)*100, 2) & "%" -> 80% | AE39: 3f55e3736fcbbe899d500195c2f67491 | AF39: =INT(E39) -> 45908 | AG39: =_xlfn.XLOOKUP(AE39, Dev!$A:$A, Dev!$B:$B, "") -> 45740.809 | AH39: =AF39-AG39 -> 167.19108
A40: 38 | B40: b927ec761b9bbe899d5001992786f2c8 | C40: 7029962 | D40: 6122514 | E40: 45899 | F40: 45905 | G40: Bệnh viện đa khoa Xanh Pôn | H40: Viêm họng cấp, viêm phổi | I40: SMART | J40: 45908.47 | K40: =MONTH(J40) -> 9 | L40: 2025 | M40: 2025 | N40: 2025 | O40: 2025 | P40: REIMBURSEMENT_CLAIM | Q40: API | R40: 45509 | S40: 1 | T40: CHILDREN | U40: MALE | V40: INPATIENT | W40: Viêm họng cấp, viêm phổi | X40: Hô hấp | Y40: 0-17 | Z40: =IF(S40<=6,"0-6", IF(S40<=17,"7-17", IF(S40<=35,"18-35", IF(S40<=55,"36-55", "56+")))) -> 0-6 | AA40: 2ffc5971401abe899d5001921ce3bde1 | AB40: 1 | AC40: {=_xlfn.SWITCH(AB40, 79,"Thành phố Hồ Chí Minh", 1,"Thành phố Hà Nội", 35,"Tỉnh Hà Nam", 31,"Thành phố Hải Phòng", 27,"Tỉnh Bắc Ninh", 77,"Tỉnh Bà Rịa - Vũng Tàu", 48,"Thành phố Đà Nẵng", 75,"Tỉnh Đồng Nai", 38,"Tỉnh Thanh Hoá", 82,"Tỉnh Tiền Giang", 74,"Tỉnh Bình Dương", 49,"Tỉnh Quảng Nam", 51,"Tỉnh Quảng Ngãi", 52,"Tỉnh Bình Định", 40,"Tỉnh Nghệ An", "Không xác định" )} -> Thành phố Hà Nội | AD40: =ROUND((D40/C40)*100, 2) & "%" -> 87.09% | AE40: 8865ceff401abe899d5001921ce3bd0e | AF40: =INT(E40) -> 45899 | AG40: =_xlfn.XLOOKUP(AE40, Dev!$A:$A, Dev!$B:$B, "") -> 45559.43 | AH40: =AF40-AG40 -> 339.57014
...

Sheet Dev
A1: contractId | B1: contractStartDate
A2: 00ef5bfd087cbe899d5001909189131e | B2: 45477
A3: 02afe4643f13be899d500189b53d45a6 | B3: 45141.621
A4: 0519adfd6fcbbe899d50019632f320cc | B4: 45762.555
A5: 08093cd26a92be899d50018a72ddfecd | B5: 45544
A6: 0bd22bfd1018be899d50018cfcb88048 | B6: 45304.632
A7: 0c4023fa5893be899d50018738344f60 | B7: 45017
A8: 0db09cfe1eecbe899d5001951229a40c | B8: 45706.478
A9: 0f2c16f83815be899d50019878e5ffe2 | B9: 45875.576
A10: 130220fe6fcbbe899d5001960a90e183 | B10: 45754.713
A11: 13a313964e44be899d50018a03012090 | B11: 45087
A12: 14f057fe7652be899d500191c58ebb58 | B12: 45542.472
A13: 1864f1fa5c0fbe899d5001957e4be942 | B13: 45727.475
... A156: ff96bcfc169ebe899d50018e98b01664 | B156: 45374
